Workbook
Name BaseMNComp: #REF!
Name BaseMNComp: #REF!
Name BaseMNComp: #REF!
Name BaseMNComp: #REF!
Name database: #REF!
Name database: #REF!
Name database: #REF!
Name database: #REF!

Sheet Synthèse >>>

Sheet Recettes
B1: V&M - Evolution des recettes du budget général
K4: En millions d'euros
C5: Désignation des recettes | D5: Exécution 2023 | E5: Évaluation initiale pour 2024 LFI | F5: Évaluation révisée pour 2024 PLF 2025 | G5: Ecarts entre les évaluations pour 2024 et proposées pour 2025 | K5: Evaluation proposée pour 2025 PLF 2025
G6: Effet de l'évolution spontanée | H6: Mesures antèrieures au présent PLF | I6: Mesures nouvelles du présent PLF | J6: Mesures de périmètre et de transfert
C7: A Recettes fiscales | D7: =SUM(D8:D16) -> 4.6022492e+11 | E7: =SUM(E8:E16) -> 4.8467127e+11 | F7: =SUM(F8:F16) -> 467588064529 | G7: =SUM(G8:G16) -> 7.3957125e+09 | H7: =SUM(H8:H16) -> 6.8977507e+09 | I7: =SUM(I8:I16) -> 1.4726926e+10 | J7: =SUM(J8:J16) -> 3741000000 | K7: =SUM(K8:K16) -> 500349453471
B8: 1101 | C8: 1 Impôt brut sur le revenu | D8: 1.1207625e+11 | E8: 117074600000 | F8: 113693585081 | G8: =K8-F8-H8-I8-J8 -> 5.8828297e+09 | H8: =RFN!H9 -> 4.8107311e+08 | I8: =RFN!I9 -> 134000000 | J8: =RFN!J9 -> 0 | K8: =RFN!K9 -> 120191487848
B9: 1201 | C9: 2 Autres impôts directs perçus par voie d'émission de rôles | D9: 2.4506473e+09 | E9: 2.6323995e+09 | F9: 2848300000 | G9: =K9-F9-H9-I9-J9 -> 50600000 | H9: =RFN!H33 -> 0 | I9: =RFN!I33 -> 0 | J9: =RFN!J33 -> 0 | K9: =RFN!K33 -> 2898900000
B10: 1301 | C10: 3 Impôt brut sur les sociétés | D10: 8.2712089e+10 | E10: 91291375411 | F10: 84059983697 | G10: =K10-F10-H10-I10-J10 -> -2.9463747e+09 | H10: =RFN!H18 -> -1.5135009e+09 | I10: =RFN!I18 -> 169079015 | J10: =RFN!J18 -> 0 | K10: =RFN!K18 -> 79769187030
B11: 1302 | C11: 3bis Contribution sociale nette sur les bénéfices des sociétés | D11: 1.4063841e+09 | E11: 1741600000 | F11: 1591000000 | G11: =K11-F11-H11-I11-J11 -> -16000000 | H11: =RFN!H34 -> 0 | I11: =RFN!I34 -> 0 | J11: =RFN!J34 -> 0 | K11: =RFN!K34 -> 1575000000
B12: 1303 | C12: 3ter Contribution de la Caisse des dépôts et consignations représentative de l'impôt sur les sociétés | D12: 313629013 | E12: 341000000 | F12: 586000000 | G12: =K12-F12-H12-I12-J12 -> -281000000 | H12: =RFN!H35 -> 0 | I12: =RFN!I35 -> 0 | J12: =RFN!J35 -> 0 | K12: =RFN!K35 -> 305000000
B13: 14 | C13: 4 Autres impôts directs et taxes assimilées | D13: 3.1466227e+10 | E13: 30283750000 | F13: 30683151465 | G13: =K13-F13-H13-I13-J13 -> -68073980 | H13: =SUM(RFN!H36:H58) -> -1.2840976e+09 | I13: =SUM(RFN!I36:I58) -> 1.1103847e+10 | J13: =SUM(RFN!J36:J58) -> 0 | K13: =SUM(RFN!K36:K58) -> 40434826658
B14: 1501 | C14: 5 Taxe intérieure de consommation sur les produits énergétiques | D14: 1.8714018e+10 | E14: 1.7379831e+10 | F14: 17582731842 | G14: =K14-F14-H14-I14-J14 -> -6.0306333e+08 | H14: =RFN!H24 -> 4.8729302e+08 | I14: =RFN!I24 -> 0 | J14: =RFN!J24 -> 591000000 | K14: =RFN!K24 -> 18057961535
B15: 1601 | C15: 6 Taxe sur la valeur ajoutée | D15: 1.7280049e+11 | E15: 184258641099 | F15: 176938872861 | G15: =K15-F15-H15-I15-J15 -> 4.7318093e+09 | H15: =RFN!H28 -> 4.3830106e+09 | I15: =RFN!I28 -> 1620000000 | J15: =RFN!J28 -> 2227000000 | K15: =RFN!K28 -> 189900692698
B16: 17 | C16: 7 Enregistrement, timbre, autres contributions et taxes indirectes | D16: 3.8285187e+10 | E16: 39668072661 | F16: 39604439583 | G16: =K16-F16-H16-I16-J16 -> 6.4498557e+08 | H16: =SUM(RFN!H59:H97) -> 4.3439725e+09 | I16: =SUM(RFN!I59:I97) -> 1700000000 | J16: =SUM(RFN!J59:J97) -> 923000000 | K16: =SUM(RFN!K59:K97) -> 47216397702
C17: B Remboursements et dégrèvements | D17: =SUM(D18:D22) -> 1.3732197e+11 | E17: =SUM(E18:E22) -> 136189146022 | F17: =SUM(F18:F22) -> 145100552381 | G17: =SUM(G18:G22) -> -1.5065815e+09 | H17: =SUM(H18:H22) -> -852000000 | I17: =SUM(I18:I22) -> 0 | J17: =SUM(J18:J22) -> 0 | K17: =SUM(K18:K22) -> 1.4274007e+11
C18: 1 Impôt sur le revenu | D18: =D8-D25 -> 2.3486808e+10 | E18: =E8-E25 -> 23710122325 | F18: =F8-F25 -> 25625616716 | G18: =G8-G25 -> 768615849 | H18: =SUM(RFN!H10:H15) -> 0 | I18: =SUM(RFN!I10:I15) -> 0 | J18: =SUM(RFN!J10:J15) -> 0 | K18: 26393233000
C19: 2 Impôt sur les sociétés | D19: =D10-D26 -> 2.5886728e+10 | E19: =E10-E26 -> 19244530370 | F19: =F10-F26 -> 26360103835 | G19: =G10-G26 -> -2836542872 | H19: =SUM(RFN!H19:H21) -> 0 | I19: =SUM(RFN!I19:I21) -> 0 | J19: =SUM(RFN!J19:J21) -> 0 | K19: 23523054000
C20: 3 Taxe intérieure de consommation sur les produits énergétiques | D20: =D14-D27 -> 1.9104711e+09 | E20: =E14-E27 -> 1989754450 | F20: =F14-F27 -> 2051043219 | G20: =G14-G27 -> -488996101 | H20: =RFN!H25 -> 0 | I20: =RFN!I25 -> 0 | J20: =RFN!J25 -> 0 | K20: =K14-K27 -> 1562047118
C21: 4 Taxe sur la valeur ajoutée | D21: =D15-D28 -> 7.7612812e+10 | E21: =E15-E28 -> 83452829859 | F21: =F15-F28 -> 80887970414 | G21: =G15-G28 -> 2790141587 | H21: =SUM(RFN!H29:H30) -> 0 | I21: =SUM(RFN!I29:I30) -> 0 | J21: =SUM(RFN!J29:J30) -> 0 | K21: =K15-K28 -> 83678112001
C22: 5 Autres remboursements et dégrèvements d'impôts d'État (y compris CSB) | D22: =D9+D11+D12+D13+D16-D29 -> 8.4251552e+09 | E22: =E9+E11+E12+E13+E16-E29 -> 7791909018 | F22: =F9+F11+F12+F13+F16-F29 -> 10175818197 | G22: =G9+G11+G12+G13+G16-G29 -> -1.7398e+09 | H22: =SUM(RFN!H98:H108) -> -852000000 | I22: =SUM(RFN!I98:I108) -> 0 | J22: =SUM(RFN!J98:J108) -> 0 | K22: =K9+K11+K12+K13+K16-K29 -> 7.5836251e+09
C24: C Recettes fiscales nettes* | D24: =SUM(D25:D29) -> 3.2290295e+11 | E24: =SUM(E25:E29) -> 3.4848212e+11 | F24: =SUM(F25:F29) -> 322487512148 | G24: =SUM(G25:G29) -> 8.902294e+09 | H24: =SUM(H25:H29) -> 7.7497507e+09 | I24: =SUM(I25:I29) -> 1.4726926e+10 | J24: =SUM(J25:J29) -> 3741000000 | K24: =RFN!K6 -> 3.5760788e+11
B25: 11net | C25: 1 Impôt sur le revenu net | D25: 8.858944e+10 | E25: 93364477675 | F25: 88067968365 | G25: =K25-F25-H25-I25-J25 -> 5.1142138e+09 | H25: =H8-H18 -> 4.8107311e+08 | I25: =I8-I18 -> 134000000 | J25: =J8-J18 -> 0 | K25: =RFN!K8 -> 93797255283
B26: 13net | C26: 2 Impôt sur les sociétés net** | D26: 5.6825361e+10 | E26: 72046845041 | F26: 57699879862 | G26: =K26-F26-H26-I26-J26 -> -1.0983187e+08 | H26: =H10-H19 -> -1.5135009e+09 | I26: =I10-I19 -> 169079015 | J26: =J10-J19 -> 0 | K26: =RFN!K17 -> 56245626067
B27: 15net | C27: 3 TICPE nette | D27: 1.6803547e+10 | E27: 1.5390077e+10 | F27: 15531688623 | G27: =K27-F27-H27-I27-J27 -> -1.1406723e+08 | H27: =H14-H20 -> 4.8729302e+08 | I27: =I14-I20 -> 0 | J27: =J14-J20 -> 591000000 | K27: =RFN!K23 -> 16495914417
B28: 16net | C28: 4 Taxe sur la valeur ajoutée nette | D28: 9.5187678e+10 | E28: 100805811240 | F28: 96050902447 | G28: =K28-F28-H28-I28-J28 -> 1.9416677e+09 | H28: =H15-H21 -> 4.3830106e+09 | I28: =I15-I21 -> 1620000000 | J28: =J15-J21 -> 2227000000 | K28: =RFN!K27 -> 106222580697
B29: autresnet | C29: 5 Autres recettes fiscales nettes | D29: 6.5496919e+10 | E29: 6.6874913e+10 | F29: 65137072851 | G29: =RFN!G32 -> 2.0703116e+09 | H29: =RFN!H32 -> 3.911875e+09 | I29: =RFN!I32 -> 1.2803847e+10 | J29: =RFN!J32 -> 923000000 | K29: =K24-SUM(K25:K28) -> 8.4846499e+10
C30: D Recettes non fiscales | D30: =RNF!D6 -> 25138915235 | E30: =RNF!E6 -> 22703930278 | F30: =RNF!F6 -> 23396639517 | G30: =RNF!G6 -> -2848091305 | H30: =RNF!H6 -> 0 | I30: =RNF!I6 -> 0 | J30: =RNF!J6 -> 0 | K30: =RNF!K6 -> 20548548212
C31: E Prélèvements sur les recettes de l'État | D31: =D32+D33 -> 6.8127153e+10 | E31: =E32+E33 -> 66667449534 | F31: =F32+F33 -> 67197134320 | G31: =G32+G33 -> 312618680 | H31: =H32+H33 -> 0 | I31: =I32+I33 -> 0 | J31: =J32+J33 -> 0 | K31: =K32+K33 -> 67509753000
C32: 1 Prélèvements sur les recettes de l'État au profit des collectivités territoriales | D32: 4.4254013e+10 | E32: 45057825520 | F32: 44940983320 | G32: =K32-F32-H32-I32-J32 -> -752085372 | H32: 0 | I32: 0 | J32: 0 | K32: 44188897948
C33: 2 Prélèvement sur les recettes de l'État au profit de l'Union européenne | D33: 2.387314e+10 | E33: 21609624014 | F33: 22256151000 | G33: =K33-F33-H33-I33-J33 -> 1064704052 | H33: 0 | I33: 0 | J33: 0 | K33: 23320855052
C34: Recettes totales nettes des prélèvements | D34: =D24+D30-D31 -> 2.7991471e+11 | E34: =E24+E30-E31 -> 3.045186e+11 | F34: =F24+F30-F31 -> 278687017345 | G34: =G24+G30-G31 -> 5.741584e+09 | H34: =H24+H30-H31 -> 7.7497507e+09 | I34: =I24+I30-I31 -> 1.4726926e+10 | J34: =J24+J30-J31 -> 3741000000 | K34: =K24+K30-K31 -> 3.1064667e+11
C35: F Fonds de concours et attributions de produits | D35: 6491691402 | E35: 7398632983 | F35: 6778522735 | G35: =K35-F35-H35-I35-J35 -> -628223957 | H35: 0 | I35: 0 | J35: 0 | K35: 6150298778
C36: Recettes nettes totales du budget général y compris fonds de concours | D36: =SUM(D34,D35) -> 2.864064e+11 | E36: =SUM(E34,E35) -> 3.1191724e+11 | F36: =SUM(F34,F35) -> 285465540080 | G36: =SUM(G34,G35) -> 5.11336e+09 | H36: =SUM(H34,H35) -> 7.7497507e+09 | I36: =SUM(I34,I35) -> 1.4726926e+10 | J36: =SUM(J34,J35) -> 3741000000 | K36: =SUM(K34,K35) -> 3.1679697e+11
C37: * A la suite de la loi organique du 28 décembre 2021 relative à la modernisation de la gestion des finances publiques, les recettes fiscales nettes sont définies comme la différence entre les recettes fiscales brutes et les remboursements et dégrèvements d’impôts d’Etat uniquement, les remboursements et dégrèvements d’impôts locaux étant désormais comptabilisés en dépenses. Cette nouvelle définition a été appliquée pour la première fois dans le cadre de la LFI pour 2023. Les chiffres 2022 présentés ci-dessus ont été retraités afin de permettre une comparaison à périmètre constant, ceux-ci étant auparavant également minorés des remboursements et dégrèvements d’impôts locaux.
C38: **Intégrant toutes les lignes 13XX

Sheet MN au présent PLF
A1: V&M - Tableau récapitulatif des mesures nouvelles au présent PLF
B4: Impôt | C4: Ligne budgétaire | D4: Libellé | E4: Nature | F4: 2025
B5: IR | C5: 1101 | D5: Suppression de niche à l'IR sur les loueurs meublés | E5: Mesure nouvelle | F5: 180000000
B6: IR | C6: 1101 | D6: Transformation de la déduction en faveur des stocks de vaches laitières et allaitantes | E6: Mesure nouvelle | F6: -46000000
B7: IS | C7: 1301 | D7: Taxe exceptionnelle due par les entreprises du fret maritime | E7: Mesure nouvelle | F7: 500000000
B8: IS | C8: 1301 | D8: Suspension de la baisse de CVAE - effet IS | E8: Mesure nouvelle | F8: -110920985
B9: IS | C9: 1301 | D9: Hausse des accises sur l'énergie (baisse de facture d'électricité d'environ 9%) - effet retour IS | E9: Mesure nouvelle | F9: -220000000
B10: Autres RFN | C10: 1497 | D10: Suspension de la baisse de CVAE | E10: Mesure nouvelle | F10: 1.1038468e+09
B11: Autres RFN | C11: 1440 | D11: Contribution différentielle applicable à certains contribuables titulaires de très hauts revenus | E11: Mesure nouvelle | F11: 2000000000
B12: Autres RFN | C12: 1441 | D12: Contribution exceptionnelle sur les bénéfices des grandes entreprises | E12: Mesure nouvelle | F12: 8000000000
B13: TVA | C13: 1601 | D13: Arrêt du taux réduit de TVA sur les abonnements à l'électricité et au gaz | E13: Mesure nouvelle | F13: 1200000000
B14: TVA | C14: 1601 | D14: Hausse des accises sur l'énergie - effet retour TVA | E14: Mesure nouvelle | F14: 220000000
B15: TVA | C15: 1601 | D15: Mise en conformité de la TVA sur les chaudières à gaz | E15: Mesure nouvelle | F15: 200000000
B16: Autres RFN | C16: 1726 | D16: Malus automobile | E16: Mesure nouvelle | F16: 300000000
... B19: Autres RFN | C19: 1796 | D19: Fiscalisation des rachats d'actions | E19: Mesure nouvelle | F19: 200000000
B20: Mesures nouvelles au présent PLF | F20: =SUM(F5:F19) -> 1.4726926e+10

Sheet MP et MT
A1: V&M - Tableau récapitulatif des mesures de périmètre et de transfert
H4: En millions d'euros
D5: Mesures de périmètre | E5: Mesures de transfert | H5: Total 2025
E6: Collectivités territoriales | F6: Sécurité sociale | G6: Autres
B7: Total mesures de transfert et de périmètre | D7: =D8+D11+D13 -> 0 | E7: =E8+E11+E13 -> 1227000000 | F7: =F8+F11+F13 -> 1000000000 | G7: =G8+G11+G13 -> 1514000000 | H7: =H8+H11+H13 -> 3741000000
B8: TVA | D8: =SUM(D9:D9) -> 0 | E8: =SUM(E9:E10) -> 1227000000 | F8: =SUM(F9:F10) -> 1000000000 | G8: =SUM(G9:G10) -> 0 | H8: =SUM(H9:H10) -> 2227000000
B9: 1601 | C9: Stabilisation du transfert de la fraction de TVA transférée aux APUL | D9: 0 | E9: 1227000000 | F9: 0 | G9: 0 | H9: =SUM(E9:G9) -> 1227000000
B10: 1601 | C10: Transfert de TVA pour couvrir l'effet retour IS sur la mesure des AG | D10: 0 | E10: 0 | F10: 1000000000 | G10: 0 | H10: =SUM(E10:G10) -> 1000000000
B11: TICPE | D11: =SUM(D12:D12) -> 0 | E11: =SUM(E12:E12) -> 0 | F11: =SUM(F12:F12) -> 0 | G11: =SUM(G12:G12) -> 591000000 | H11: =SUM(H12:H12) -> 591000000
B12: 1501 | C12: Baisse de la TICPE affectée à l'AFITF | D12: 0 | E12: 0 | F12: 0 | G12: 591000000 | H12: =SUM(E12:G12) -> 591000000
B13: Autres RFN | D13: =SUM(D14:D17) -> 0 | E13: =SUM(E14:E17) -> 0 | F13: =SUM(F14:F17) -> 0 | G13: =SUM(G14:G17) -> 923000000 | H13: =SUM(H14:H17) -> 923000000
B14: 1753 | C14: Affectation de TICFE pour financer le surcoût lié à la production d'électricité dans les ZNI | D14: 0 | E14: 0 | F14: 0 | G14: -2800000000 | H14: =SUM(E14:G14) -> -2800000000
B15: 1797 | C15: Budgétisation de la TTF affectée au FSD | D15: 0 | E15: 0 | F15: 0 | G15: 528000000 | H15: =SUM(E15:G15) -> 528000000
B16: 1799 | C16: Budgétisation du 1% logement affecté au FNAL | D16: 0 | E16: 0 | F16: 0 | G16: 2985000000 | H16: =SUM(E16:G16) -> 2985000000
B17: 1799 | C17: Budgétisation de la TSBA affectée au FSD | D17: 0 | E17: 0 | F17: 0 | G17: 210000000 | H17: =SUM(E17:G17) -> 210000000

Sheet Détails >>>

Sheet RNF
A1: V&M - Tableau récapitulatif des recettes non fiscales
K3: En millions d'euros
B4: Ligne | C4: Désignation des recettes | D4: Exécution 2023 | E4: Évaluation initiale pour 2024 LFI | F4: Évaluation révisée pour 2024 PLF 2025 | G4: Ecarts entre les évaluations pour 2024 et proposées pour 2025 | K4: Evaluation proposée pour 2025 PLF 2025
G5: Effet de l'évolution spontanée | H5: Mesures antèrieures au présent PLF | I5: Mesures nouvelles du présent PLF | J5: Mesures de périmètre et de transfert
C6: Recettes non fiscales | D6: =D8+D13+D22+D30+D40+D51 -> 25138915235 | E6: =E8+E13+E22+E30+E40+E51 -> 22703930278 | F6: =F8+F13+F22+F30+F40+F51 -> 23396639517 | G6: =G8+G13+G22+G30+G40+G51 -> -2848091305 | H6: =H8+H13+H22+H30+H40+H51 -> 0 | I6: =I8+I13+I22+I30+I40+I51 -> 0 | J6: =J8+J13+J22+J30+J40+J51 -> 0 | K6: =K8+K13+K22+K30+K40+K51 -> 20548548212
B8: 21 | C8: Dividendes et recettes assimilées | D8: =SUM(D9:D11) -> 3870401948 | E8: =SUM(E9:E11) -> 3154700000 | F8: =SUM(F9:F11) -> 4749817225 | G8: =SUM(G9:G11) -> 1203140910 | H8: =SUM(H9:H11) -> 0 | I8: =SUM(I9:I11) -> 0 | J8: =SUM(J9:J11) -> 0 | K8: =SUM(K9:K11) -> 5952958135
B9: 2110 | C9: Produits des participations de l'Etat dans des entreprises financières | D9: 1599739436 | E9: 1578700000 | F9: 1539075190 | G9: =K9-F9-H9-I9-J9 -> -72475190 | H9: 0 | I9: 0 | J9: 0 | K9: 1466600000
B10: 2116 | C10: Produits des participations de l'Etat dans des entreprises non financières et bénéfices des établissements publics non financiers | D10: 2255880377 | E10: 1576000000 | F10: 2352259900 | G10: =K10-F10-H10-I10-J10 -> 2119316100 | H10: 0 | I10: 0 | J10: 0 | K10: 4471576000
B11: 2199 | C11: Autres dividendes et recettes assimilées | D11: 14782135 | E11: 0 | F11: 858482135 | G11: =K11-F11-H11-I11-J11 -> -843700000 | H11: 0 | I11: 0 | J11: 0 | K11: 14782135
B13: 22 | C13: Produits du domaine de l’Etat | D13: =SUM(D14:D20) -> 1162786281 | E13: =SUM(E14:E20) -> 1745107200 | F13: =SUM(F14:F20) -> 1553389632 | G13: =SUM(G14:G20) -> 70291296 | H13: =SUM(H14:H20) -> 0 | I13: =SUM(I14:I20) -> 0 | J13: =SUM(J14:J20) -> 0 | K13: =SUM(K14:K20) -> 1623680928
B14: 2201 | C14: Revenus du domaine public non militaire | D14: 472048926 | E14: 1025000000 | F14: 851048926 | G14: =K14-F14-H14-I14-J14 -> 60000000 | H14: 0 | I14: 0 | J14: 0 | K14: 911048926
B15: 2202 | C15: Autres revenus du domaine public | D15: 10062136 | E15: 7989520 | F15: 10384627 | G15: =K15-F15-H15-I15-J15 -> 278790 | H15: 0 | I15: 0 | J15: 0 | K15: 10663417
B16: 2203 | C16: Revenus du domaine privé | D16: 360036278 | E16: 293117680 | F16: 371575444 | G16: =K16-F16-H16-I16-J16 -> 9975441 | H16: 0 | I16: 0 | J16: 0 | K16: 381550885
B17: 2204 | C17: Redevances d'usage des fréquences radioélectriques | D17: 319291345 | E17: 417000000 | F17: 319000000 | G17: =K17-F17-H17-I17-J17 -> 0 | H17: 0 | I17: 0 | J17: 0 | K17: 319000000
B18: 2209 | C18: Paiement par les administrations de leurs loyers budgétaires | D18: 0 | E18: 0 | F18: 0 | G18: =K18-F18-H18-I18-J18 -> 0 | H18: 0 | I18: 0 | J18: 0 | K18: 0
B19: 2212 | C19: Autres produits de cessions d'actifs | D19: 9836 | E19: 0 | F19: 0 | G19: =K19-F19-H19-I19-J19 -> 0 | H19: 0 | I19: 0 | J19: 0 | K19: 0
B20: 2299 | C20: Autres revenus du domaine | D20: 1337760 | E20: 2000000 | F20: 1380635 | G20: =K20-F20-H20-I20-J20 -> 37065 | H20: 0 | I20: 0 | J20: 0 | K20: 1417700
B22: 23 | C22: Produits de la vente de biens et services | D22: =SUM(D23:D28) -> 3137611484 | E22: =SUM(E23:E28) -> 3543928718 | F22: =SUM(F23:F28) -> 2597573264 | G22: =SUM(G23:G28) -> -57017030 | H22: =SUM(H23:H28) -> 0 | I22: =SUM(I23:I28) -> 0 | J22: =SUM(J23:J28) -> 0 | K22: =SUM(K23:K28) -> 2540556234
B23: 2301 | C23: Remboursement par les Communautés européennes des frais d'assiette et de perception des impôts et taxes perçus au profit de son budget | D23: 654321704 | E23: 778000000 | F23: 632027240 | G23: =K23-F23-H23-I23-J23 -> 34574418 | H23: 0 | I23: 0 | J23: 0 | K23: 666601658
B24: 2303 | C24: Autres frais d'assiette et de recouvrement | D24: 1025147230 | E24: 1101058634 | F24: 1061144531 | G24: =K24-F24-H24-I24-J24 -> 25262192 | H24: 0 | I24: 0 | J24: 0 | K24: 1086406723
B25: 2304 | C25: Rémunération des prestations assurées par les services du Trésor public au titre de la collecte de l'épargne | D25: 35169884 | E25: 52013515 | F25: 36404849 | G25: =K25-F25-H25-I25-J25 -> 866674 | H25: 0 | I25: 0 | J25: 0 | K25: 37271523
B26: 2305 | C26: Produits de la vente de divers biens | D26: 16227 | E26: 67669 | F26: 16797 | G26: =K26-F26-H26-I26-J26 -> 400 | H26: 0 | I26: 0 | J26: 0 | K26: 17197
B27: 2306 | C27: Produits de la vente de divers services | D27: 3382613 | E27: 4788900 | F27: 3501391 | G27: =K27-F27-H27-I27-J27 -> 83356 | H27: 0 | I27: 0 | J27: 0 | K27: 3584747
B28: 2399 | C28: Autres recettes diverses | D28: 1419573826 | E28: 1608000000 | F28: 864478456 | G28: =K28-F28-H28-I28-J28 -> -117804070 | H28: 0 | I28: 0 | J28: 0 | K28: 746674386
B30: 24 | C30: Remboursements et intérêts des prêts, avances et autres immobilisations financières | D30: =SUM(D31:D38) -> 740572995 | E30: =SUM(E31:E38) -> 1181753301 | F30: =SUM(F31:F38) -> 1193837865 | G30: =SUM(G31:G38) -> 73413854 | H30: =SUM(H31:H38) -> 0 | I30: =SUM(I31:I38) -> 0 | J30: =SUM(J31:J38) -> 0 | K30: =SUM(K31:K38) -> 1267251719
B31: 2401 | C31: Intérêts des prêts à des banques et à des Etats étrangers | D31: 390737713 | E31: 450000000 | F31: 406000000 | G31: =K31-F31-H31-I31-J31 -> -54000000 | H31: 0 | I31: 0 | J31: 0 | K31: 352000000
B32: 2402 | C32: Intérêts des prêts du fonds de développement économique et social | D32: 15013585 | E32: 17630396 | F32: 15540776 | G32: =K32-F32-H32-I32-J32 -> 22140771 | H32: 0 | I32: 0 | J32: 0 | K32: 37681547
B33: 2403 | C33: Intérêts des avances à divers services de l'Etat ou organismes gérant des services publics | D33: 77937680 | E33: 96400000 | F33: 84607089 | G33: =K33-F33-H33-I33-J33 -> -11551265 | H33: 0 | I33: 0 | J33: 0 | K33: 73055824
B34: 2409 | C34: Intérêts des autres prêts et avances | D34: 75638897 | E34: 130250000 | F34: 130000000 | G34: =K34-F34-H34-I34-J34 -> 0 | H34: 0 | I34: 0 | J34: 0 | K34: 130000000
B35: 2411 | C35: Avances remboursables sous conditions consenties à l'aviation civile | D35: 87497427 | E35: 109382905 | F35: 109600000 | G35: =K35-F35-H35-I35-J35 -> -8700000 | H35: 0 | I35: 0 | J35: 0 | K35: 100900000
B36: 2412 | C36: Autres avances remboursables sous conditions | D36: 0 | E36: 0 | F36: 0 | G36: =K36-F36-H36-I36-J36 -> 0 | H36: 0 | I36: 0 | J36: 0 | K36: 0
B37: 2413 | C37: Reversement au titre des créances garanties par l'Etat | D37: 6430106 | E37: 12890000 | F37: 12890000 | G37: =K37-F37-H37-I37-J37 -> -6075652 | H37: 0 | I37: 0 | J37: 0 | K37: 6814348
B38: 2499 | C38: Autres remboursements d'avances, de prêts et d'autres créances immobilisées | D38: 87317587 | E38: 365200000 | F38: 435200000 | G38: =K38-F38-H38-I38-J38 -> 131600000 | H38: 0 | I38: 0 | J38: 0 | K38: 566800000
B40: 25 | C40: Amendes, sanctions, pénalités et frais de poursuites | D40: =SUM(D41:D49) -> 2185856993 | E40: =SUM(E41:E49) -> 2910524644 | F40: =SUM(F41:F49) -> 2727696633 | G40: =SUM(G41:G49) -> 9966776 | H40: =SUM(H41:H49) -> 0 | I40: =SUM(I41:I49) -> 0 | J40: =SUM(J41:J49) -> 0 | K40: =SUM(K41:K49) -> 2737663409
B41: 2501 | C41: Produits des amendes forfaitaires de la police de la circulation | D41: 735800924 | E41: 663084092 | F41: 786086668 | G41: =K41-F41-H41-I41-J41 -> -16208478 | H41: 0 | I41: 0 | J41: 0 | K41: 769878190
B42: 2502 | C42: Produits des amendes prononcées par les autorités de la concurrence | D42: 161720337 | E42: 700000000 | F42: 727988735 | G42: =K42-F42-H42-I42-J42 -> 0 | H42: 0 | I42: 0 | J42: 0 | K42: 727988735
B43: 2503 | C43: Produits des amendes prononcées par les autres autorités administratives indépendantes | D43: 228274323 | E43: 285000000 | F43: 116389224 | G43: =K43-F43-H43-I43-J43 -> 0 | H43: 0 | I43: 0 | J43: 0 | K43: 116389224
B44: 2504 | C44: Recouvrements poursuivis à l'initiative de l'agence judiciaire de l'Etat | D44: 12392280 | E44: 8150000 | F44: 12827426 | G44: =K44-F44-H44-I44-J44 -> 305377 | H44: 0 | I44: 0 | J44: 0 | K44: 13132803
B45: 2505 | C45: Produit des autres amendes et condamnations pécuniaires | D45: 1030474572 | E45: 1229550000 | F45: 1066658938 | G45: =K45-F45-H45-I45-J45 -> 25393471 | H45: 0 | I45: 0 | J45: 0 | K45: 1092052409
B46: 2510 | C46: Frais de poursuite | D46: 6324938 | E46: 12491893 | F46: 6527652 | G46: =K46-F46-H46-I46-J46 -> 175244 | H46: 0 | I46: 0 | J46: 0 | K46: 6702896
...

Sheet RFN
A1: V&M - Tableau récapitulatif des recettes fiscales nettes
C3: En millions d'euros
B4: Ligne | C4: Désignation des recettes | D4: Exécution 2023 | E4: Évaluation initiale pour 2024 LFI | F4: Évaluation révisée pour 2024 PLF 2025 | G4: Ecarts entre les évaluations pour 2024 et proposées pour 2025 | K4: Evaluation proposée pour 2025 PLF 2025
G5: Effet de l'évolution spontanée | H5: Mesures antèrieures au présent PLF | I5: Mesures nouvelles du présent PLF | J5: Mesures de périmètre et de transfert
C6: Recettes fiscales nettes(1) | D6: =D8+D17+D23+D27+D32 -> 3.2290295e+11 | E6: =E8+E17+E23+E27+E32 -> 3.4848212e+11 | F6: =F8+F17+F23+F27+F32 -> 322487512148 | G6: =G8+G17+G23+G27+G32 -> 8.902294e+09 | H6: =H8+H17+H23+H27+H32 -> 7.7497507e+09 | I6: =I8+I17+I23+I27+I32 -> 1.4726926e+10 | J6: =J8+J17+J23+J27+J32 -> 3741000000 | K6: 3.5760788e+11
C8: Impôt sur le revenu net | D8: =D9-SUM(D10:D15) -> 8.858944e+10 | E8: =E9-SUM(E10:E15) -> 93364477675 | F8: =F9-SUM(F10:F15) -> 88067968365 | G8: =G9-SUM(G10:G15) -> 5.1142138e+09 | H8: =H9-SUM(H10:H15) -> 4.8107311e+08 | I8: =I9-SUM(I10:I15) -> 134000000 | J8: =J9-SUM(J10:J15) -> 0 | K8: =K9-SUM(K10:K15) -> 93797255283
B9: 1101 | C9: Impôt sur le revenu brut | D9: 1.1207625e+11 | E9: 117074600000 | F9: 113693585081 | G9: =K9-F9-H9-I9-J9 -> 5.8828297e+09 | H9: 4.8107311e+08 | I9: ='MN au présent PLF'!F5+'MN au présent PLF'!F6 -> 134000000 | J9: 0 | K9: 120191487848
B10: 200-11-05 | C10: Impôt sur le revenu | D10: 12423138029 | E10: 11949000000 | F10: 13329000000 | G10: =K10-F10-H10-I10-J10 -> -6000000 | H10: 0 | I10: 0 | J10: 0 | K10: 13323000000
B11: 200-12-02 | C11: Impôt sur le revenu | D11: 2.0981935e+09 | E11: 2103000000 | F11: 2252000000 | G11: =K11-F11-H11-I11-J11 -> 0 | H11: 0 | I11: 0 | J11: 0 | K11: 2252000000
B12: 200-12-08 | C12: Acomptes de crédits et de réductions d'impôts sur le revenu | D12: 5613175642 | E12: 5370000000 | F12: 5759976540 | G12: =K12-F12-H12-I12-J12 -> -30976540 | H12: 0 | I12: 0 | J12: 0 | K12: 5729000000
B13: 200-12-10 | C13: Crédit d'impôt contemporain - Services aux particuliers | D13: 8.4559924e+08 | E13: 1888122325 | F13: 1584640176 | G13: =K13-F13-H13-I13-J13 -> 805592389 | H13: 0 | I13: 0 | J13: 0 | K13: 2390232565
B14: 200-13-01 | C14: Impôt sur le revenu - Dégrèvements et restitutions de sommes indûment perçues | D14: 2.3902531e+09 | E14: 2300000000 | F14: 2600000000 | G14: =K14-F14-H14-I14-J14 -> 0 | H14: 0 | I14: 0 | J14: 0 | K14: 2600000000
B15: 200-13-09 | C15: Prélèvement à la source (PAS) : dégrèvements et restitutions | D15: 1.1644824e+08 | E15: 100000000 | F15: 100000000 | G15: =K15-F15-H15-I15-J15 -> 0 | H15: 0 | I15: 0 | J15: 0 | K15: 100000000
C17: Impôt sur les sociétés net | D17: =D18-SUM(D19:D21) -> 5.6825361e+10 | E17: =E18-SUM(E19:E21) -> 72046845041 | F17: =F18-SUM(F19:F21) -> 57699879862 | G17: =G18-SUM(G19:G21) -> -1.0983187e+08 | H17: =H18-SUM(H19:H21) -> -1.5135009e+09 | I17: =I18-SUM(I19:I21) -> 169079015 | J17: =J18-SUM(J19:J21) -> 0 | K17: =K18-SUM(K19:K21) -> 56245626067
B18: 1301 | C18: Impôt sur les sociétés brut | D18: 8.2712089e+10 | E18: 91291375411 | F18: 84059983697 | G18: =K18-F18-H18-I18-J18 -> -2.9463747e+09 | H18: -1.5135009e+09 | I18: 169079015 | J18: 0 | K18: 79769187030
B19: 200-11-01 | C19: Impôt sur les sociétés | D19: 1.7877683e+10 | E19: 11382168515 | F19: 18454471940 | G19: =K19-F19-H19-I19-J19 -> -2933359658 | H19: 0 | I19: 0 | J19: 0 | K19: 15521112282
B20: 200-12-03 | C20: Impôt sur les sociétés | D20: 7.1492593e+09 | E20: 6337938267 | F20: 6605331940 | G20: =K20-F20-H20-I20-J20 -> 97116741 | H20: 0 | I20: 0 | J20: 0 | K20: 6702448681
B21: 200-13-02 | C21: Impôt sur les sociétés - Dégrèvements et restitutions de sommes indûment perçues | D21: 8.5978607e+08 | E21: 1524423588 | F21: 1300299955 | G21: =K21-F21-H21-I21-J21 -> -299955 | H21: 0 | I21: 0 | J21: 0 | K21: 1300000000
C23: Taxe intérieure de consommation sur les produits énergétiques nette Etat | D23: =D24-D25 -> 1.6803547e+10 | E23: =E24-E25 -> 1.5390077e+10 | F23: =F24-F25 -> 15531688623 | G23: =G24-G25 -> -1.1406723e+08 | H23: =H24-H25 -> 4.8729302e+08 | I23: =I24-I25 -> 0 | J23: =J24-J25 -> 591000000 | K23: =K24-K25 -> 16495914417
B24: 1501 | C24: Taxe intérieure de consommation sur les produits énergétiques brute Etat | D24: 1.8714018e+10 | E24: 1.7379831e+10 | F24: 17582731842 | G24: =K24-F24-H24-I24-J24 -> -6.0306333e+08 | H24: 4.8729302e+08 | J24: ='MP et MT'!G12 -> 591000000 | K24: 18057961535
B25: 200-12-04 | C25: Taxe intérieure de consommation sur les produits énergétiques | D25: 1.9104711e+09 | E25: 1989754450 | F25: 2051043219 | G25: =K25-F25-H25-I25-J25 -> -488996101 | H25: 0 | I25: 0 | J25: 0 | K25: 1562047118
C27: Taxe sur la valeur ajoutée Etat nette | D27: =D28-D29-D30 -> 9.5187678e+10 | E27: =E28-E29-E30 -> 100805811240 | F27: =F28-F29-F30 -> 96050902447 | G27: =G28-G29-G30 -> 1.9416677e+09 | H27: =H28-H29-H30 -> 4.3830106e+09 | I27: =I28-I29-I30 -> 1620000000 | J27: =J28-J29-J30 -> 2227000000 | K27: =K28-K29-K30 -> 106222580697
B28: 1601 | C28: Taxe sur la valeur ajoutée Etat brute | D28: 1.7280049e+11 | E28: 184258641099 | F28: 176938872861 | G28: =K28-F28-H28-I28-J28 -> 4.7318093e+09 | H28: 4.3830106e+09 | I28: ='MN au présent PLF'!F13+'MN au présent PLF'!F14+'MN au présent PLF'!F15 -> 1620000000 | J28: ='MP et MT'!H8 -> 2227000000 | K28: 189900692698
B29: 200-11-02 | C29: Taxe sur la valeur ajoutée | D29: 7.4017246e+10 | E29: 79326599860 | F29: 77587385418 | G29: =K29-F29-H29-I29-J29 -> 2727812663 | H29: 0 | I29: 0 | J29: 0 | K29: 80315198081
B30: 200-13-04 | C30: Taxe sur la valeur ajoutée - Dégrèvements et restitutions de sommes indûment perçues | D30: 3.5955656e+09 | E30: 4126229999 | F30: 3300584996 | G30: =K30-F30-H30-I30-J30 -> 62328924 | H30: 0 | I30: 0 | J30: 0 | K30: 3362913920
C32: Autres recettes fiscales nettes | D32: =SUM(D33:D97)-SUM(D98:D108) -> 6.5496919e+10 | E32: =SUM(E33:E97)-SUM(E98:E108) -> 6.6874913e+10 | F32: =SUM(F33:F97)-SUM(F98:F108) -> 65137072851 | G32: =SUM(G33:G97)-SUM(G98:G108) -> 2.0703116e+09 | H32: =SUM(H33:H97)-SUM(H98:H108) -> 3.911875e+09 | I32: =SUM(I33:I97)-SUM(I98:I108) -> 1.2803847e+10 | J32: =SUM(J33:J97)-SUM(J98:J108) -> 923000000 | K32: =K6-K8-K17-K23-K27 -> 8.4846499e+10
B33: 1201 | C33: Autres impôts directs perçus par voie d'émission de rôles | D33: 2.4506473e+09 | E33: 2.6323995e+09 | F33: 2848300000 | G33: =K33-F33-H33-I33-J33 -> 50600000 | H33: 0 | I33: 0 | J33: 0 | K33: 2898900000
B34: 1302 | C34: Contribution sociale sur les bénéfices des sociétés | D34: 1.4063841e+09 | E34: 1741600000 | F34: 1591000000 | G34: =K34-F34-H34-I34-J34 -> -16000000 | H34: 0 | I34: 0 | J34: 0 | K34: 1575000000
B35: 1303 | C35: Contribution de la Caisse des dépôts et consignations représentative de l'impôt sur les sociétés | D35: 313629013 | E35: 341000000 | F35: 586000000 | G35: =K35-F35-H35-I35-J35 -> -281000000 | H35: 0 | I35: 0 | J35: 0 | K35: 305000000
B36: 1401 | C36: Retenues à la source sur certains bénéfices non commerciaux et de l'impôt sur le revenu | D36: 1.3053452e+09 | E36: 1080000000 | F36: 1400000000 | G36: =K36-F36-H36-I36-J36 -> -270779901 | H36: 0 | I36: 0 | J36: 0 | K36: 1129220099
B37: 1402 | C37: Retenues à la source et prélèvements sur les revenus de capitaux mobiliers et le prélèvement sur les bons anonymes | D37: 4.9686619e+09 | E37: 4800000000 | F37: 5000000000 | G37: =K37-F37-H37-I37-J37 -> 100000000 | H37: 0 | I37: 0 | J37: 0 | K37: 5100000000
B38: 1404 | C38: Précompte dû par les sociétés au titre de certains bénéfices distribués (loi n°65-566 du 12 juillet 1965 art 3) | D38: 1.7052011e+08 | E38: 0 | F38: 0 | G38: =K38-F38-H38-I38-J38 -> 0 | H38: 0 | I38: 0 | J38: 0 | K38: 0
B39: 1405 | C39: Prélèvement exceptionnel de 25% sur les distributions de bénéfices | D39: 1135409.4 | E39: 0 | F39: 1135409 | G39: =K39-F39-H39-I39-J39 -> 0 | H39: 0 | I39: 0 | J39: 0 | K39: 1135409
B40: 1406 | C40: Impôt sur la fortune immobilière | D40: 2.3543244e+09 | E40: 2439000000 | F40: 2548301800 | G40: =K40-F40-H40-I40-J40 -> -108133518 | H40: 0 | I40: 0 | J40: 0 | K40: 2440168282
B41: 1407 | C41: Taxe sur les locaux à usage de bureaux, les locaux commerciaux et de stockage | D41: 16128379 | E41: 15000000 | F41: 16666583 | G41: =K41-F41-H41-I41-J41 -> 442726 | H41: 0 | I41: 0 | J41: 0 | K41: 17109309
B42: 1408 | C42: Prélèvements sur les entreprises d'assurance | D42: 229643508 | E42: 162000000 | F42: 154637111 | G42: =K42-F42-H42-I42-J42 -> 4107738 | H42: 0 | I42: 0 | J42: 0 | K42: 158744849
B43: 1410 | C43: Cotisation minimale de taxe professionnelle | D43: 822827.91 | E43: 1000000 | F43: 822828 | G43: =K43-F43-H43-I43-J43 -> 0 | H43: 0 | I43: 0 | J43: 0 | K43: 822828
B44: 1411 | C44: Participation employeurs à l'effort de construction | D44: 25569896 | E44: 34000000 | F44: 26423163 | G44: =K44-F44-H44-I44-J44 -> 701898 | H44: 0 | I44: 0 | J44: 0 | K44: 27125061
... B53: 1431 | C53: Taxe d'habitation sur résidence principale | D53: 4.6164955e+08 | E53: 180000000 | F53: 147161049 | G53: =K53-F53-H53-I53-J53 -> -147161049 | H53: 0 | I53: 0 | J53: 0 | K53: 0
B54: 1440 | C54: Contribution différentielle temporaire sur les très hauts revenus | D54: 0 | E54: 0 | F54: 0 | G54: =K54-F54-H54-I54-J54 -> 0 | H54: 0 | I54: ='MN au présent PLF'!F11 -> 2000000000 | J54: 0 | K54: 2000000000
...

Sheet R&D
A1: V&M - Tableau récapitulatif des remboursements et dégrèvements d'impôts d'Etat
K3: En millions d'euros
B4: Ligne | C4: Désignation des recettes | D4: Exécution 2023 | E4: Évaluation initiale pour 2024 LFI | F4: Évaluation révisée pour 2024 PLF 2025 | G4: Ecarts entre les évaluations pour 2024 et proposées pour 2025 | K4: Evaluation proposée pour 2025 PLF 2025
G5: Effet de l'évolution spontanée | H5: Mesures antèrieures au présent PLF | I5: Mesures nouvelles du présent PLF | J5: Mesures de périmètre et de transfert
B6: 200 | C6: Remboursements et dégrèvements d'impôts d'État (crédits évaluatifs) | D6: =D7+D14+D23 -> 1.3732197e+11 | E6: =E7+E14+E23 -> 136189146022 | F6: =F7+F14+F23 -> 145100552381 | G6: =G7+G14+G23 -> -3248087734 | H6: =H7+H14+H23 -> 889000000 | I6: =I7+I14+I23 -> 0 | J6: =J7+J14+J23 -> 0 | K6: =K7+K14+K23 -> 142741464648
B7: 200-11 | C7: Remboursements et restitutions liés à la mécanique de l'impôt | D7: 1.0520073e+11 | E7: 103358158375 | F7: 110506773816 | G7: =SUM(G8:G13) -> -324845793 | H7: =SUM(H8:H13) -> 0 | I7: =SUM(I8:I13) -> 0 | J7: =SUM(J8:J13) -> 0 | K7: 110181928023
B8: 200-11-01 | C8: Impôt sur les sociétés | D8: 1.7877683e+10 | E8: 11382168515 | F8: 18454471940 | G8: =K8-F8-H8-I8-J8 -> -2933858456 | H8: 0 | I8: 0 | J8: 0 | K8: 15520613484
B9: 200-11-02 | C9: Taxe sur la valeur ajoutée | D9: 7.4017246e+10 | E9: 79326599860 | F9: 77587385418 | G9: =K9-F9-H9-I9-J9 -> 2727812663 | H9: 0 | I9: 0 | J9: 0 | K9: 80315198081
B10: 200-11-03 | C10: Plafonnement des impositions directes | D10: 116458 | E10: 390000 | F10: 116458 | G10: =K10-F10-H10-I10-J10 -> 0 | H10: 0 | I10: 0 | J10: 0 | K10: 116458
B11: 200-11-04 | C11: Autres remboursements et dégrèvements liés à la mécanique de l'impôt | D11: 393713771 | E11: 200000000 | F11: 635800000 | G11: =K11-F11-H11-I11-J11 -> -112800000 | H11: 0 | I11: 0 | J11: 0 | K11: 523000000
B12: 200-11-05 | C12: Impôt sur le revenu | D12: 12423138029 | E12: 11949000000 | F12: 13329000000 | G12: =K12-F12-H12-I12-J12 -> -6000000 | H12: 0 | I12: 0 | J12: 0 | K12: 13323000000
B13: 200-11-06 | C13: Restitutions - Prélèvement de solidarité | D13: 488834398 | E13: 500000000 | F13: 500000000 | G13: =K13-F13-H13-I13-J13 -> 0 | H13: 0 | I13: 0 | J13: 0 | K13: 500000000
B14: 200-12 | C14: Remboursements et dégrèvements liés à des politiques publiques | D14: 1.8126036e+10 | E14: 17803815042 | F14: 18388293890 | G14: =SUM(G15:G22) -> 432641292 | H14: =SUM(H15:H22) -> 0 | I14: =SUM(I15:I22) -> 0 | J14: =SUM(J15:J22) -> 0 | K14: 18820935183
B15: 200-12-02 | C15: Impôt sur le revenu | D15: 2.0981935e+09 | E15: 2103000000 | F15: 2252000000 | G15: =K15-F15-H15-I15-J15 -> 0 | H15: 0 | I15: 0 | J15: 0 | K15: 2252000000
B16: 200-12-03 | C16: Impôt sur les sociétés | D16: 7.1492593e+09 | E16: 6337938267 | F16: 6605331940 | G16: =K16-F16-H16-I16-J16 -> 97021544 | H16: 0 | I16: 0 | J16: 0 | K16: 6702353484
B17: 200-12-04 | C17: Taxe intérieure de consommation sur les produits énergétiques | D17: 1.9104711e+09 | E17: 1989754450 | F17: 2051043219 | G17: =K17-F17-H17-I17-J17 -> -488996101 | H17: 0 | I17: 0 | J17: 0 | K17: 1562047118
B18: 200-12-05 | C18: Taxe intérieure de consommation sur le gaz naturel | D18: 35302015 | E18: 15000000 | F18: 35302015 | G18: =K18-F18-H18-I18-J18 -> 0 | H18: 0 | I18: 0 | J18: 0 | K18: 35302015
B19: 200-12-06 | C19: Contribution à l'audiovisuel public | D19: 0.1 | E19: 0 | F19: 0 | G19: =K19-F19-H19-I19-J19 -> 0 | H19: 0 | I19: 0 | J19: 0 | K19: 0
B20: 200-12-08 | C20: Acomptes de crédits et de réductions d'impôts sur le revenu | D20: 5613175642 | E20: 5370000000 | F20: 5759976540 | G20: =K20-F20-H20-I20-J20 -> -30976540 | H20: 0 | I20: 0 | J20: 0 | K20: 5729000000
B21: 200-12-09 | C21: Taxe intérieure sur la consommation finale d'électricité | D21: 4.7403573e+08 | E21: 100000000 | F21: 100000000 | G21: =K21-F21-H21-I21-J21 -> 50000000 | H21: 0 | I21: 0 | J21: 0 | K21: 150000000
B22: 200-12-10 | C22: Crédit d'impôt contemporain - Services aux particuliers | D22: 8.4559924e+08 | E22: 1888122325 | F22: 1584640176 | G22: =K22-F22-H22-I22-J22 -> 805592389 | H22: 0 | I22: 0 | J22: 0 | K22: 2390232565
B23: 200-13 | C23: Remboursements et dégrèvements liés à la gestion des produits de l'Etat | D23: 1.3995206e+10 | E23: 15027172605 | F23: 16205484675 | G23: =SUM(G24:G32) -> -3355883233 | H23: =SUM(H24:H32) -> 889000000 | I23: =SUM(I24:I32) -> 0 | J23: =SUM(J24:J32) -> 0 | K23: 13738601442
B24: 200-13-01 | C24: Impôt sur le revenu - Dégrèvements et restitutions de sommes indûment perçues | D24: 2.3902531e+09 | E24: 2300000000 | F24: 2600000000 | G24: =K24-F24-H24-I24-J24 -> 0 | H24: 0 | I24: 0 | J24: 0 | K24: 2600000000
B25: 200-13-02 | C25: Impôt sur les sociétés - Dégrèvements et restitutions de sommes indûment perçues | D25: 8.5978607e+08 | E25: 1524423588 | F25: 1300299955 | G25: =K25-F25-H25-I25-J25 -> -212157 | H25: 0 | I25: 0 | J25: 0 | K25: 1300087798
B26: 200-13-03 | C26: Autres impôts directs et taxes assimilées - Dégrèvements et restitutions de sommes indûment perçues | D26: 2.1351803e+09 | E26: 2982719649 | F26: 3569000000 | G26: =K26-F26-H26-I26-J26 -> -2440400000 | H26: 889000000 | I26: 0 | J26: 0 | K26: 2017600000
B27: 200-13-04 | C27: Taxe sur la valeur ajoutée - Dégrèvements et restitutions de sommes indûment perçues | D27: 3.5955656e+09 | E27: 4126229999 | F27: 3300584996 | G27: =K27-F27-H27-I27-J27 -> 62328924 | H27: 0 | I27: 0 | J27: 0 | K27: 3362913920
B28: 200-13-05 | C28: Enregistrement, timbre, autres contributions et taxes indirectes - Dégrèvements et restitutions de sommes indûment perçues | D28: 6.5403194e+08 | E28: 680000000 | F28: 700000000 | G28: =K28-F28-H28-I28-J28 -> 0 | H28: 0 | I28: 0 | J28: 0 | K28: 700000000
B29: 200-13-06 | C29: Autres remboursements et dégrèvements liés à la gestion des produits de l'État | D29: 1.3875278e+09 | E29: 715757000 | F29: 1184000000 | G29: =K29-F29-H29-I29-J29 -> -284000000 | H29: 0 | I29: 0 | J29: 0 | K29: 900000000
B30: 200-13-07 | C30: Autres remboursements et dégrèvements liés à la gestion des produits de l'État- Admissions en non valeur- Créances liées aux impôts | D30: 2.2494042e+09 | E30: 1968042369 | F30: 2994599724 | G30: =K30-F30-H30-I30-J30 -> -724000000 | H30: 0 | I30: 0 | J30: 0 | K30: 2270599724
B31: 200-13-08 | C31: Autres remboursements et dégrèvements liés à la gestion des produits de l'État- Dations en paiement, intérêts moratoires, remises de débets | D31: 6.0700853e+08 | E31: 630000000 | F31: 457000000 | G31: =K31-F31-H31-I31-J31 -> 30400000 | H31: 0 | I31: 0 | J31: 0 | K31: 487400000
B32: 200-13-09 | C32: Prélèvement à la source (PAS) : dégrèvements et restitutions | D32: 1.1644824e+08 | E32: 100000000 | F32: 100000000 | G32: =K32-F32-H32-I32-J32 -> 0 | H32: 0 | I32: 0 | J32: 0 | K32: 100000000

Sheet MN, MT et MP
A1: V&M - Base de données des mesures nouvelles et de transfert chiffrées
B4: Impôt | C4: Lignes budgétaires | D4: Intitulé de la mesure | E4: Références | F4: 2023 | G4: 2024 | H4: 2025
B5: CVAE | C5: 1497 | D5: Suppression de la CVAE Etat | E5: LFI/LFSS_2023 | F5: -4.1609245e+09 | G5: -371000000 | H5: 0
B6: CVAE | C6: 1497 | D6: Suppression de la CVAE - Budgétisation de la CVAE à l'Etat | E6: LFI/LFSS_2023 | F6: 9.8948208e+09 | G6: 0 | H6: 0
B7: AutresRFN | C7: 1201 | D7: Suppression de la CVAE - Effet transfert de FAR à l'Etat | E7: LFI/LFSS_2023 | F7: -87157268 | G7: -5581369.8 | H7: 0
B8: TVA | C8: 1601 | D8: Suppression de la CVAE - Transfert de TVA aux Apul | E8: LFI/LFSS_2023 | F8: -10492000000 | G8: 0 | H8: 0
D9: Suppression partielle de la CVAE | F9: =SUM(F5:F8) -> -4.845261e+09 | G9: =SUM(G5:G8) -> -3.7658137e+08 | H9: =SUM(H5:H8) -> 0
B11: TVA | C11: 1601 | D11: Hausse du transfert de TVA au CCF audiovisuel | E11: LFI/LFSS_2024 | F11: 0 | G11: -228000000 | H11: 0
B12: TVA | C12: 1601 | D12: Transfert de TVA au compte d'avances audiovisuel jusque fin de 2024 en compensation de la suppression de la contribution sur l'audiovisuel | E12: LFR1_2022 | F12: -212000000 | G12: 0 | H12: 0
D13: Suppression de la redevance audiovisuelle | F13: =SUM(F11:F12) -> -212000000 | G13: =SUM(G11:G12) -> -228000000 | H13: =SUM(H11:H12) -> 0
B15: TICPE | C15: 1501 | D15: Hausse tarifs GNR non agricole (5,99 cts€ / an) – TICPE | E15: LFI/LFSS_2024 | F15: 0 | G15: 1.417234e+08 | H15: 1.417234e+08
B16: TICPE | C16: 1501 | D16: Aménagements tarifs GNR agricole – TICPE | E16: Autres_2024 | F16: 0 | G16: -2.8682498e+08 | H16: 2.1502884e+08
D17: Remplacement suppression niche GNR | F17: =SUM(F15:F16) -> 0 | G17: =SUM(G15:G16) -> -1.4510158e+08 | H17: =SUM(H15:H16) -> 3.5675224e+08
B19: IR | C19: 1101 | D19: Relèvement de 5 000 € à 7 500 € du plafond de défiscalisation pour les heures supplémentaires et complémentaires effectuées par les salariés à compter du 1er janvier 2022 | E19: LFR1_2022 | F19: -160000000 | G19: 80000000 | H19: 0
D20: Relèvement du plafond de défiscalisation des heures supplémentaires | F20: =F19 -> -160000000 | G20: =G19 -> 80000000 | H20: =H19 -> 0
B22: IS | C22: 1301 | D22: Nouveaux paramètres et prorogation du crédit d'impôt eco-PTZ | E22: LFI/LFSS_2024 | F22: -4419000 | G22: -48000000 | H22: -74000000
B23: IS | C23: 1301 | D23: Nouveaux paramètres et prorogation du crédit d'impôt PTZ | E23: LFI/LFSS_2024 | F23: 1.4065951e+08 | G23: 27000000 | H23: 2000000
D24: PTZ | F24: =SUM(F22:F23) -> 1.3624051e+08 | G24: =SUM(G22:G23) -> -21000000 | H24: =SUM(H22:H23) -> -72000000
B26: IR | C26: 1101 | D26: Création d'une provision pour stock de vaches | E26: LFI/LFSS_2024 | F26: 0 | G26: -90000000 | H26: 0
D27: Provision pour stock de vaches | F27: =SUM(F26:F26) -> 0 | G27: =SUM(G26:G26) -> -90000000 | H27: =SUM(H26:H26) -> 0
B29: IR | C29: 1101 | D29: Prorogation du Pinel jusqu’en 2024 | E29: LFI/LFSS_2021 | F29: -2.3063453e+08 | G29: -1.5471486e+08 | H29: -1.2418525e+08
D30: Pinel | F30: =SUM(F29:F29) -> -2.3063453e+08 | G30: =SUM(G29:G29) -> -1.5471486e+08 | H30: =SUM(H29:H29) -> -1.2418525e+08
B32: IS | C32: 1301 | D32: CICE - hausse de taux - impact IS | E32: LFI/LFSS_2017 | F32: 1.2659641e+08 | G32: -1.2659641e+08 | H32: 0
D33: Montée en charge et hausse de taux CICE | F33: =F32 -> 1.2659641e+08 | G33: =G32 -> -1.2659641e+08 | H33: =H32 -> 0
B35: AutresRFN | C35: 1726 | D35: Renforcement du malus CO2 (ligne 1726) | E35: LFI/LFSS_2024 | F35: 0 | G35: 200000000 | H35: 300000000
D36: Mesures de gage industrie verte | F36: =F35 -> 0 | G36: =G35 -> 200000000 | H36: =H35 -> 300000000
B38: CVAE | C38: 1497 | D38: Lissage en 4 ans de la CVAE | E38: LFI/LFSS_2024 | F38: 0 | G38: -1110000000 | H38: -1.2860976e+09
B39: CVAE | C39: 1497 | D39: Suspension de la baisse de CVAE | E39: LFI/LFSS_2025 | F39: 0 | G39: 0 | H39: 1.1038468e+09
B40: IS | C40: 1301 | D40: Lissage en 4 ans de la CVAE - Effet retour IS | E40: LFI/LFSS_2024 | F40: 0 | G40: 1.554e+08 | H40: 3.140045e+08
B41: IS | C41: 1301 | D41: Suspension de la baisse de CVAE - effet IS | E41: LFI/LFSS_2025 | F41: 0 | G41: 0 | H41: -1.1092099e+08
B42: IS | C42: 1301 | D42: Suppression de la CVAE - Effet retour IS | E42: LFI/LFSS_2023 | F42: 5.9470699e+08 | G42: 5.6570826e+08 | H42: -2.0690921e+08
D43: Lissage de la CVAE | F43: =SUM(F38:F42) -> 5.9470699e+08 | G43: =SUM(G38:G42) -> -3.8889174e+08 | H43: =SUM(H38:H42) -> -1.8607653e+08
B45: TICPE | C45: 200-12-04 | D45: Fiscalité sur l'énergie - annulation de la composante carbone en TICPE 2019 à 2022 - impact R&D | E45: LFI/LFSS_2019 | F45: 186000000 | G45: 0 | H45: 0
B46: AutresRFN | C46: 1753 | D46: Fiscalité sur l'énergie - annulation de la composante carbone en TICPE 2019 à 2022 - impact TICGN | E46: LFI/LFSS_2019 | F46: -143000000 | G46: 0 | H46: 0
B47: AutresRFN | C47: 1753 | D47: Fiscalité sur l'énergie - impact TICGN - 2018 | E47: LFI/LFSS_2018 | F47: 142900000 | G47: 0 | H47: 0
B48: TICPE | C48: 200-12-04 | D48: Fiscalité sur l'énergie - hausse de la composante carbone en TICPE - Impact R&D - 2018 | E48: LFI/LFSS_2018 | F48: -1.8552e+08 | G48: 0 | H48: 0
D49: Hausse de la fiscalité énergétique | F49: =SUM(F45:F48) -> 380000 | G49: =SUM(G45:G48) -> 0 | H49: =SUM(H45:H48) -> 0
B51: AutresRFN | C51: 1753 | D51: Normalisation fiscalité énergétique TICFE | E51: Autres_2023 | F51: 0 | G51: 3490000000 | H51: 4.3157059e+09
B52: AutresRFN | C52: 1753 | D52: Prolongation TICFE bouclier tarifaire électricité au périmètre TCCFE | E52: LFI/LFSS_2023 | F52: -1.1315437e+09 | G52: -2.9178172e+08 | H52: 0
B53: AutresRFN | C53: 200-12-09 | D53: TICFE bouclier tarifaire électricité - effet R&D | E53: LFI/LFSS_2022 | F53: -439000000 | G53: 1.15e+09 | H53: 0
...

Sheet Art. 25 LO 2021-1836
B1: Tableau relatif à l'art. 25 de la loi organique 2021-1836 du 28 décembre 2021 relative à la modernisation de la gestion des finances publiques
B3: Impôt | C3: Lignes budgétaires | D3: Intitulé de la mesure | E3: Dispositif concerné | F3: Références | G3: Année d'entrée en vigueur | H3: 2023 | I3: 2024 | J3: 2025
B4: TVA | C4: 1601 | D4: Hausse du transfert de TVA au CCF audiovisuel | E4: Suppression de la CAP | F4: Autres_2024 | G4: 2024 | I4: -0.228
B5: TICPE | C5: 1501 | D5: Aménagements tarifs GNR agricole – TICPE | E5: Remplacement suppression niche GNR | F5: Autres_2024 | G5: 2024 | I5: -0.28682498 | J5: 0.21502884
B6: Autres RFN | C6: 1799 | D6: Hausse de la contribution sur les contrats d'assurance (régime Cat Nat) | F6: Autres_2024 | G6: 2025 | J6: 0.15
B7: IR | C7: 1101 | D7: Création d'une provision pour stock de vaches | E7: Provision pour stock de vaches | F7: LFI/LFSS_2024 | G7: 2024 | I7: -0.09
B9: Les mesures ayant une incidence budgétaire inférieure à 50 M€ ne sont pas affichées dans le tableau
